package ExceptionHandling;

public class NestedTryCatchBlock {
    public static void main(String[]args){
        try {
            //Outer try block
            System.out.println("Outer try block started.");
            try {
                //Inner try block 1
                int n = 10;
                int res = n / 0;

            } catch (ArithmeticException e){
                System.out.println("Caught Arithmetic Exception in inner try-catch: " + e);
            }
            try {
                //Inner try block 2
                String s = null;
                System.out.println(s.length());
            } catch (NullPointerException e){
                System.out.println("Caught NullPointerException in inner try-catch: " + e);
            }
        } catch (Exception e){
            //Outer catch block
            System.out.println("Caught exception in outer try-catch: " + e);
        } finally {
            //Finally block
            System.out.println("Finally block executed");
        }
    }
}
